Workbook
Name avg_equity: Ratios!$C$27
Name avg_total_assets: Ratios!$C$28
Name avg_total_capitalization: Ratios!$C$29
Name book_equity: Ratios!$C$18
Name cash: Ratios!$C$19
Name cogs: Ratios!$C$38
Name cost_of_capital: Ratios!$C$7
Name current_assets_total: Ratios!$C$20
Name current_liabilities_total: Ratios!$C$21
Name currentYear_after_tax_operating_income: Ratios!$C$16
Name currentYear_assets_total: Ratios!$C$24
Name currentYear_total_capitalization: Ratios!$C$25
Name daily_sales: Ratios!$C$17
Name depreciation_amortization: Ratios!$C$39
Name ebit: Ratios!$C$32
Name interest_total: Ratios!$C$33
Name inventory_current: Ratios!$C$36
Name long_term_debt: Ratios!$C$22
Name long_term_debt_plus_equity: Ratios!$C$30
Name market_capitalization: Ratios!$C$9
Name net_income: Ratios!$C$35
Name nwc: Ratios!$C$23
Name pretax_profit: Ratios!$C$34
Name receivables_current: Ratios!$C$37
Name revenue: Ratios!$C$31
Name share_price: Ratios!$C$5
Name shares_outstanding: Ratios!$C$6
Name startYear_assets_total: Ratios!$C$13
Name startYear_equity: Ratios!$C$10
Name startYear_inventories: Ratios!$C$11
Name startYear_lt_debt: Ratios!$C$14
Name startYear_receivables: Ratios!$C$12
Name startYear_total_capitalization: Ratios!$C$15
Name tax_rate: Ratios!$C$8
Name total_liabilities: Ratios!$C$26

Sheet Balance Sheet
A1: Caterpillar Inc. – Balance Sheet (FY2025 / FY2024)
A3: Line Item | B3: FY2025 ($mm) | C3: FY2024 ($mm) | D3: Notes
A4: Cash and cash equivalents | B4: 9980 | C4: 6889 | D4: Values mapped from Caterpillar 2025 Form 10-K Excel data.
A5: Receivables - trade and other | B5: 10920 | C5: 9282 | D5: Values mapped from Caterpillar 2025 Form 10-K Excel data.
A6: Receivables - finance | B6: 10649 | C6: 9565 | D6: Values mapped from Caterpillar 2025 Form 10-K Excel data.
A7: Prepaid expenses and other current assets | B7: 2801 | C7: 3119 | D7: Values mapped from Caterpillar 2025 Form 10-K Excel data.
A8: Inventories | B8: 18135 | C8: 16827 | D8: Values mapped from Caterpillar 2025 Form 10-K Excel data.
A9: Total current assets | B9: 52485 | C9: 45682 | D9: Values mapped from Caterpillar 2025 Form 10-K Excel data.
A10: Property, plant and equipment - net | B10: 15140 | C10: 13361 | D10: Values mapped from Caterpillar 2025 Form 10-K Excel data.
A11: Long-term receivables - trade and other | B11: 2142 | C11: 1225 | D11: Values mapped from Caterpillar 2025 Form 10-K Excel data.
A12: Long-term receivables - finance | B12: 14272 | C12: 13242 | D12: Values mapped from Caterpillar 2025 Form 10-K Excel data.
A13: Noncurrent deferred and refundable income taxes | B13: 2882 | C13: 3312 | D13: Values mapped from Caterpillar 2025 Form 10-K Excel data.
A14: Intangible assets | B14: 241 | C14: 399 | D14: Values mapped from Caterpillar 2025 Form 10-K Excel data.
A15: Goodwill | B15: 5321 | C15: 5241 | D15: Values mapped from Caterpillar 2025 Form 10-K Excel data.
... A39: Total liabilities and shareholders' equity | B39: 98585 | C39: 87764 | D39: Values mapped from Caterpillar 2025 Form 10-K Excel data.

Sheet Income Statement
A1: Caterpillar Inc. – Income Statement (FY2025 / FY2024)
A3: Line Item | B3: FY2025 ($mm) | C3: FY2024 ($mm) | D3: Notes
A4: Sales of Machinery, Power & Energy | B4: 63980 | C4: 61363 | D4: Values mapped from Caterpillar 2025 Form 10-K Excel data.
A5: Revenues of Financial Products | B5: 3609 | C5: 3446 | D5: Values mapped from Caterpillar 2025 Form 10-K Excel data.
A6: Total sales and revenues | B6: 67589 | C6: 64809 | D6: Values mapped from Caterpillar 2025 Form 10-K Excel data.
A7: Cost of goods sold | B7: 44752 | C7: 40199 | D7: Values mapped from Caterpillar 2025 Form 10-K Excel data.
A8: Selling, general and administrative expenses | B8: 6985 | C8: 6667 | D8: Values mapped from Caterpillar 2025 Form 10-K Excel data.
A9: Research and development expenses | B9: 2148 | C9: 2107 | D9: Values mapped from Caterpillar 2025 Form 10-K Excel data.
A10: Interest expense of Financial Products | B10: 1359 | C10: 1286 | D10: Values mapped from Caterpillar 2025 Form 10-K Excel data.
A11: Other operating (income) expenses | B11: 1194 | C11: 1478 | D11: Values mapped from Caterpillar 2025 Form 10-K Excel data.
A12: Total operating costs | B12: 56438 | C12: 51737 | D12: Values mapped from Caterpillar 2025 Form 10-K Excel data.
A13: Operating profit (EBIT) | B13: 11151 | C13: 13072 | D13: Values mapped from Caterpillar 2025 Form 10-K Excel data.
A14: Interest expense excluding Financial Products | B14: 502 | C14: 512 | D14: Values mapped from Caterpillar 2025 Form 10-K Excel data.
A15: Other income (expense) | B15: 892 | C15: 813 | D15: Values mapped from Caterpillar 2025 Form 10-K Excel data.
... A23: Diluted EPS | B23: 18.81 | C23: 22.05 | D23: Values mapped from Caterpillar 2025 Form 10-K Excel data.

Sheet Cash Flow
A1: Caterpillar Inc. – Cash Flow Statement (FY2025 / FY2024)
A3: Line Item | B3: FY2025 ($mm) | C3: FY2024 ($mm) | D3: Notes
A4: Profit of consolidated and affiliated companies | B4: 8882 | C4: 10788 | D4: Values mapped from Caterpillar 2025 Form 10-K Excel data.
A5: Depreciation and amortization | B5: 2262 | C5: 2153 | D5: Values mapped from Caterpillar 2025 Form 10-K Excel data.
A6: Provision (benefit) for deferred income taxes | B6: 465 | C6: -621 | D6: Values mapped from Caterpillar 2025 Form 10-K Excel data.
A7: (Gain) loss on divestiture | B7: 30 | C7: 164 | D7: Values mapped from Caterpillar 2025 Form 10-K Excel data.
A8: Receivables - trade and other | B8: -2138 | C8: -160 | D8: Values mapped from Caterpillar 2025 Form 10-K Excel data.
A9: Inventories | B9: -1477 | C9: -414 | D9: Values mapped from Caterpillar 2025 Form 10-K Excel data.
A10: Accounts payable | B10: 1179 | C10: -282 | D10: Values mapped from Caterpillar 2025 Form 10-K Excel data.
A11: Accrued expenses | B11: 438 | C11: 191 | D11: Values mapped from Caterpillar 2025 Form 10-K Excel data.
A12: Accrued wages, salaries and employee benefits | B12: 187 | C12: -363 | D12: Values mapped from Caterpillar 2025 Form 10-K Excel data.
A13: Customer advances | B13: 1933 | C13: 370 | D13: Values mapped from Caterpillar 2025 Form 10-K Excel data.
A14: Other assets - net | B14: -176 | C14: -97 | D14: Values mapped from Caterpillar 2025 Form 10-K Excel data.
A15: Other liabilities - net | B15: -294 | C15: -104 | D15: Values mapped from Caterpillar 2025 Form 10-K Excel data.
... A26: Cash, cash equivalents and restricted cash at end of period | B26: 9986 | C26: 6896 | D26: Values mapped from Caterpillar 2025 Form 10-K Excel data.

Sheet Ratios
A1: Caterpillar Inc. – Ratio Model (latest available data)
A3: Named Range / Key | B3: Description | C3: Value | D3: Units | E3: Source / Formula Note
A5: share_price | B5: Share price (entered from IR trade history) | C5: 716.33 | D5: USD/share | E5: Assumption / market input; update as needed
A6: shares_outstanding | B6: Shares outstanding at Dec. 31 | C6: ='Income Statement'!B22 -> 465.3 | D6: mm shares | E6: Linked from Income Statement
A7: cost_of_capital | B7: Cost of capital (WACC) | C7: 0.1 | D7: % | E7: Editable assumption
A8: tax_rate | B8: Effective tax rate | C8: ='Income Statement'!B17/'Income Statement'!B16 -> 0.23984057 | D8: % | E8: Provision for taxes / pretax profit
A9: market_capitalization | B9: Market capitalization | C9: =C5*C6 -> 333308.35 | D9: $mm | E9: Share price × shares outstanding
A10: startYear_equity | B10: Beginning equity (FY2024) | C10: ='Balance Sheet'!C38 -> 19494 | D10: $mm | E10: Prior-year balance sheet
A11: startYear_inventories | B11: Beginning inventories (FY2024) | C11: ='Balance Sheet'!C8 -> 16827 | D11: $mm | E11: Prior-year balance sheet
A12: startYear_receivables | B12: Beginning receivables - trade and other (FY2024) | C12: ='Balance Sheet'!C5 -> 9282 | D12: $mm | E12: Prior-year balance sheet
A13: startYear_assets_total | B13: Beginning total assets (FY2024) | C13: ='Balance Sheet'!C17 -> 87764 | D13: $mm | E13: Prior-year balance sheet
A14: startYear_lt_debt | B14: Beginning long-term debt (FY2024) | C14: ='Balance Sheet'!C28+'Balance Sheet'!C29 -> 27351 | D14: $mm | E14: LT debt due after one year
A15: startYear_total_capitalization | B15: Beginning total capitalization (LT debt + equity) | C15: =C14+C10 -> 46845 | D15: $mm | E15: Beginning LT debt + beginning equity
A16: currentYear_after_tax_operating_income | B16: Current-year after-tax operating income (NOPAT) | C16: ='Income Statement'!B13*(1-C8) -> 8476.5378 | D16: $mm | E16: EBIT × (1-tax rate)
A17: daily_sales | B17: Current-year daily sales | C17: ='Income Statement'!B6/365 -> 185.17534 | D17: $mm/day | E17: Revenue ÷ 365
A18: book_equity | B18: Current-year book equity | C18: ='Balance Sheet'!B38 -> 21318 | D18: $mm | E18: Current-year total shareholders' equity
A19: cash | B19: Current-year cash | C19: ='Balance Sheet'!B4 -> 9980 | D19: $mm | E19: Current-year cash and cash equivalents
A20: current_assets_total | B20: Current-year current assets | C20: ='Balance Sheet'!B9 -> 52485 | D20: $mm | E20: Current-year total current assets
A21: current_liabilities_total | B21: Current-year current liabilities | C21: ='Balance Sheet'!B27 -> 36558 | D21: $mm | E21: Current-year total current liabilities
A22: long_term_debt | B22: Current-year long-term debt (due after one year) | C22: ='Balance Sheet'!B28+'Balance Sheet'!B29 -> 30696 | D22: $mm | E22: Current-year LT debt due after one year
A23: nwc | B23: Net working capital | C23: =C20-C21 -> 15927 | D23: $mm | E23: Current assets - current liabilities
A24: currentYear_assets_total | B24: Current-year total assets | C24: ='Balance Sheet'!B17 -> 98585 | D24: $mm | E24: Current-year total assets
A25: currentYear_total_capitalization | B25: Current-year total capitalization | C25: =C22+C18 -> 52014 | D25: $mm | E25: Current LT debt + current equity
A26: total_liabilities | B26: Current-year total liabilities | C26: ='Balance Sheet'!B32 -> 77267 | D26: $mm | E26: Current-year total liabilities
A27: avg_equity | B27: Average equity | C27: =(C10+C18)/2 -> 20406 | D27: $mm | E27: Average of beginning and ending equity
A28: avg_total_assets | B28: Average total assets | C28: =(C13+C24)/2 -> 93174.5 | D28: $mm | E28: Average of beginning and ending total assets
A29: avg_total_capitalization | B29: Average total capitalization | C29: =(C15+C25)/2 -> 49429.5 | D29: $mm | E29: Average of beginning and ending capitalization
A30: long_term_debt_plus_equity | B30: Long-term debt + equity | C30: =C22+C18 -> 52014 | D30: $mm | E30: Same as current-year total capitalization
A31: revenue | B31: Current-year sales and revenues | C31: ='Income Statement'!B6 -> 67589 | D31: $mm | E31: Current-year total sales and revenues
A32: ebit | B32: Current-year EBIT | C32: ='Income Statement'!B13 -> 11151 | D32: $mm | E32: Current-year operating profit
A33: interest_total | B33: Total interest expense | C33: ='Income Statement'!B10+'Income Statement'!B14 -> 1861 | D33: $mm | E33: Financial Products interest + ex-FP interest
A34: pretax_profit | B34: Pretax profit | C34: ='Income Statement'!B16 -> 11541 | D34: $mm | E34: Consolidated profit before taxes
A35: net_income | B35: Profit attributable to common shareholders | C35: ='Income Statement'!B19 -> 8884 | D35: $mm | E35: Net income used for ROE and EPS
A36: inventory_current | B36: Current-year inventory | C36: ='Balance Sheet'!B8 -> 18135 | D36: $mm | E36: Current-year inventories
A37: receivables_current | B37: Current-year receivables - trade and other | C37: ='Balance Sheet'!B5 -> 10920 | D37: $mm | E37: Current-year receivables - trade and other
A38: cogs | B38: Cost of goods sold | C38: ='Income Statement'!B7 -> 44752 | D38: $mm | E38: Current-year cost of goods sold
A39: depreciation_amortization | B39: Depreciation and amortization | C39: ='Cash Flow'!B5 -> 2262 | D39: $mm | E39: Current-year D&A from cash flow statement
A41: Ratio Calculations
A42: Category | B42: Ratio | C42: Computed Value | D42: Formula in named-range notation | E42: Comment
A43: Performance | B43: Market Value Added (MVA) | C43: =C9-C18 -> 311990.35 | D43: market_capitalization - book_equity | E43: Equity market value less book equity
...

Sheet Notes
A1: Notes / Sources / Assumptions
A3: Type | B3: Detail | C3: URL | D3: Status
A4: Primary SEC source | B4: Latest Caterpillar 10-K filing detail page. Current fiscal year in model = FY2025; prior year = FY2024. | C4: https://www.sec.gov/Archives/edgar/data/18230/000001823026000008/0000018230-26-000008-index.htm | D4: Used
A5: Investor Relations filing source | B5: Caterpillar IR filing details page for the FY2025 Form 10-K, including downloadable Excel data. | C5: https://investors.caterpillar.com/financials/sec-filings/sec-filings-details/default.aspx?FilingId=19144813 | D5: Used
A6: Investor results source | B6: 4Q and full-year 2025 results page used as a cross-check for FY2025 revenue, operating margin, enterprise operating cash flow and enterprise cash. | C6: https://investors.caterpillar.com/news/news-details/2026/Caterpillar-Reports-Fourth-Quarter-and-Full-Year-2025-Results/default.aspx | D6: Used
A7: Investor market source | B7: Share price input uses Caterpillar IR stock trade history. Entered model price = 716.33, trade date April 7, 2026. | C7: https://investors.caterpillar.com/stock-info/stock-trade-history/default.aspx | D7: Used
A8: Yahoo Finance source | B8: Yahoo quote page used as a market-cap cross-check (snippet showed market cap of about $333.71B at time of access). | C8: https://finance.yahoo.com/quote/CAT/ | D8: Used
A9: Assumption | B9: Cost of capital (WACC) is a model assumption and remains editable. | D9: Review
A10: Assumption | B10: Ratios are calculated from direct worksheet cell references so they display correctly even if spreadsheet apps mishandle named ranges. | D10: Used
A11: Method note | B11: Named ranges are still defined on the Ratios input cells for auditability and to match the course convention. | D11: Used
A12: Check | B12: DuPont ROA should exactly match average ROA, and DuPont ROE should exactly match average ROE within rounding. | D12: Pass
A13: Check | B13: Market capitalization is calculated as share price × shares outstanding; compare to Yahoo market cap as a reasonableness check. | D13: Pass
